<sdf version='1.6'>
  <world name='default'>
    <light name='sun' type='directional'>
      <cast_shadows>1</cast_shadows>
      <pose frame=''>0 0 10 0 -0 0</pose>
      <diffuse>0.8 0.8 0.8 1</diffuse>
      <specular>0.1 0.1 0.1 1</specular>
      <attenuation>
        <range>1000</range>
        <constant>0.9</constant>
        <linear>0.01</linear>
        <quadratic>0.001</quadratic>
      </attenuation>
      <direction>-0.5 0.5 -1</direction>
    </light>
    <model name='ground_plane'>
      <static>1</static>
      <link name='link'>
        <collision name='collision'>
          <geometry>
            <plane>
              <normal>0 0 1</normal>
              <size>100 100</size>
            </plane>
          </geometry>
          <surface>
            <friction>
              <ode>
                <mu>100</mu>
                <mu2>50</mu2>
              </ode>
              <torsional>
                <ode/>
              </torsional>
            </friction>
            <contact>
              <ode/>
            </contact>
            <bounce/>
          </surface>
          <max_contacts>10</max_contacts>
        </collision>
        <visual name='visual'>
          <cast_shadows>0</cast_shadows>
          <geometry>
            <plane>
              <normal>0 0 1</normal>
              <size>100 100</size>
            </plane>
          </geometry>
          <material>
            <script>
              <uri>file://media/materials/scripts/gazebo.material</uri>
              <name>Gazebo/Grey</name>
            </script>
          </material>
        </visual>
        <self_collide>0</self_collide>
        <kinematic>0</kinematic>
        <gravity>1</gravity>
      </link>
    </model>
    <gravity>0 0 -9.8</gravity>
    <magnetic_field>6e-06 2.3e-05 -4.2e-05</magnetic_field>
    <atmosphere type='adiabatic'/>
    <physics name='default_physics' default='0' type='ode'>
      <max_step_size>0.001</max_step_size>
      <real_time_factor>1</real_time_factor>
      <real_time_update_rate>1000</real_time_update_rate>
    </physics>
    <scene>
      <ambient>0.4 0.4 0.4 1</ambient>
      <background>0.7 0.7 0.7 1</background>
      <shadows>1</shadows>
    </scene>
    <spherical_coordinates>
      <surface_model>EARTH_WGS84</surface_model>
      <latitude_deg>0</latitude_deg>
      <longitude_deg>0</longitude_deg>
      <elevation>0</elevation>
      <heading_deg>0</heading_deg>
    </spherical_coordinates>
    <model name='robot_arm'>
      <link name='robot_arm_base_link'>
        <pose frame=''>0 0 0 0 -0 0</pose>
        <inertial>
          <pose frame=''>0 0 0 1.5708 -0 0</pose>
          <mass>1024</mass>
          <inertia>
            <ixx>170.667</ixx>
            <ixy>0</ixy>
            <ixz>0</ixz>
            <iyy>170.667</iyy>
            <iyz>0</iyz>
            <izz>170.667</izz>
          </inertia>
        </inertial>
        <collision name='robot_arm_base_link_collision'>
          <pose frame=''>0 0 0 1.5708 -0 0</pose>
          <geometry>
            <mesh>
              <scale>1 1 1</scale>
              <uri>/home/bouich/catkin_ws/src/robot_arm/meshes/Base_new.stl</uri>
            </mesh>
          </geometry>
          <max_contacts>10</max_contacts>
          <surface>
            <contact>
              <ode/>
            </contact>
            <bounce/>
            <friction>
              <torsional>
                <ode/>
              </torsional>
              <ode/>
            </friction>
          </surface>
        </collision>
        <visual name='robot_arm_base_link_visual'>
          <pose frame=''>0 0 0 1.5708 -0 0</pose>
          <geometry>
            <mesh>
              <scale>1 1 1</scale>
              <uri>/home/bouich/catkin_ws/src/robot_arm/meshes/Base_new.stl</uri>
            </mesh>
          </geometry>
        </visual>
        <self_collide>0</self_collide>
        <kinematic>0</kinematic>
        <gravity>1</gravity>
      </link>
      <link name='robot_arm_turning_mount'>
        <pose frame=''>0 -0.07 0.06 0 -0 0</pose>
        <inertial>
          <pose frame=''>0 0 0 1.5708 0 -1.5708</pose>
          <mass>15.7633</mass>
          <inertia>
            <ixx>1.3235</ixx>
            <ixy>0</ixy>
            <ixz>0</ixz>
            <iyy>1.235</iyy>
            <iyz>0</iyz>
            <izz>1.3235</izz>
          </inertia>
        </inertial>
        <collision name='robot_arm_turning_mount_collision'>
          <pose frame=''>0 0 0 1.5708 0 -1.5708</pose>
          <geometry>
            <mesh>
              <scale>1 1 1</scale>
              <uri>/home/bouich/catkin_ws/src/robot_arm/meshes/Turning_mount.stl</uri>
            </mesh>
          </geometry>
          <max_contacts>10</max_contacts>
          <surface>
            <contact>
              <ode/>
            </contact>
            <bounce/>
            <friction>
              <torsional>
                <ode/>
              </torsional>
              <ode/>
            </friction>
          </surface>
        </collision>
        <visual name='robot_arm_turning_mount_visual'>
          <pose frame=''>0 0 0 1.5708 0 -1.5708</pose>
          <geometry>
            <mesh>
              <scale>1 1 1</scale>
              <uri>/home/bouich/catkin_ws/src/robot_arm/meshes/Turning_mount.stl</uri>
            </mesh>
          </geometry>
        </visual>
        <self_collide>0</self_collide>
        <kinematic>0</kinematic>
        <gravity>1</gravity>
      </link>
      <joint name='robot_arm_base_link__robot_arm_turning_mount' type='revolute'>
        <child>robot_arm_turning_mount</child>
        <parent>robot_arm_base_link</parent>
        <axis>
          <xyz>0 0 1</xyz>
          <limit>
            <lower>-3.14</lower>
            <upper>3.14</upper>
            <effort>1000</effort>
            <velocity>0.5</velocity>
          </limit>
          <dynamics>
            <spring_reference>0</spring_reference>
            <spring_stiffness>0</spring_stiffness>
          </dynamics>
          <use_parent_model_frame>1</use_parent_model_frame>
        </axis>
      </joint>
      <link name='robot_arm_link2'>
        <pose frame=''>-0.005 -0.06 0.095 -1.57079 1.57079 1.57079</pose>
        <inertial>
          <pose frame=''>-0.15 0 0 0 -0 0</pose>
          <mass>5.7906</mass>
          <inertia>
            <ixx>1.2679</ixx>
            <ixy>0</ixy>
            <ixz>0</ixz>
            <iyy>1.2679</iyy>
            <iyz>0</iyz>
            <izz>0.0651</izz>
          </inertia>
        </inertial>
        <collision name='robot_arm_link2_collision'>
          <pose frame=''>-0.15 0 0 0 -0 0</pose>
          <geometry>
            <mesh>
              <scale>1 1 1</scale>
              <uri>/home/bouich/catkin_ws/src/robot_arm/meshes/Link1.stl</uri>
            </mesh>
          </geometry>
          <max_contacts>10</max_contacts>
          <surface>
            <contact>
              <ode/>
            </contact>
            <bounce/>
            <friction>
              <torsional>
                <ode/>
              </torsional>
              <ode/>
            </friction>
          </surface>
        </collision>
        <visual name='robot_arm_link2_visual'>
          <pose frame=''>-0.15 0 0 0 -0 0</pose>
          <geometry>
            <mesh>
              <scale>1 1 1</scale>
              <uri>/home/bouich/catkin_ws/src/robot_arm/meshes/Link1.stl</uri>
            </mesh>
          </geometry>
        </visual>
        <self_collide>0</self_collide>
        <kinematic>0</kinematic>
        <gravity>1</gravity>
      </link>
      <joint name='robot_arm_turning_mount__robot_arm_link2' type='revolute'>
        <child>robot_arm_link2</child>
        <parent>robot_arm_turning_mount</parent>
        <axis>
          <xyz>-1 7e-06 0</xyz>
          <limit>
            <lower>-2.8</lower>
            <upper>2.8</upper>
            <effort>1000</effort>
            <velocity>0.5</velocity>
          </limit>
          <dynamics>
            <spring_reference>0</spring_reference>
            <spring_stiffness>0</spring_stiffness>
          </dynamics>
          <use_parent_model_frame>1</use_parent_model_frame>
        </axis>
      </joint>
      <link name='robot_arm_link4'>
        <pose frame=''>-0.007 -0.060001 0.245 -3.14159 0 3.14158</pose>
        <inertial>
          <pose frame=''>-0.002 -0.02 -0.07 0 -0 0</pose>
          <mass>0.5906</mass>
          <inertia>
            <ixx>0.2679</ixx>
            <ixy>0</ixy>
            <ixz>0</ixz>
            <iyy>0.2679</iyy>
            <iyz>0</iyz>
            <izz>0.0651</izz>
          </inertia>
        </inertial>
        <collision name='robot_arm_link4_collision'>
          <pose frame=''>-0.002 -0.02 -0.07 0 -0 0</pose>
          <geometry>
            <mesh>
              <scale>1 1 1</scale>
              <uri>/home/bouich/catkin_ws/src/robot_arm/meshes/Link3_section_1.stl</uri>
            </mesh>
          </geometry>
          <max_contacts>10</max_contacts>
          <surface>
            <contact>
              <ode/>
            </contact>
            <bounce/>
            <friction>
              <torsional>
                <ode/>
              </torsional>
              <ode/>
            </friction>
          </surface>
        </collision>
        <visual name='robot_arm_link4_visual'>
          <pose frame=''>-0.002 -0.02 -0.07 0 -0 0</pose>
          <geometry>
            <mesh>
              <scale>1 1 1</scale>
              <uri>/home/bouich/catkin_ws/src/robot_arm/meshes/Link3_section_1.stl</uri>
            </mesh>
          </geometry>
        </visual>
        <self_collide>0</self_collide>
        <kinematic>0</kinematic>
        <gravity>1</gravity>
      </link>
      <joint name='robot_arm_link2__robot_arm_link4' type='revolute'>
        <child>robot_arm_link4</child>
        <parent>robot_arm_link2</parent>
        <axis>
          <xyz>-1 1.1e-05 0</xyz>
          <limit>
            <lower>-3.14</lower>
            <upper>3.14</upper>
            <effort>1000</effort>
            <velocity>0.5</velocity>
          </limit>
          <dynamics>
            <spring_reference>0</spring_reference>
            <spring_stiffness>0</spring_stiffness>
          </dynamics>
          <use_parent_model_frame>1</use_parent_model_frame>
        </axis>
      </joint>
      <link name='robot_arm_link5'>
        <pose frame=''>-0.007 -0.065 0.32 -3.14159 0 3.14158</pose>
        <inertial>
          <pose frame=''>0.005 0 -0.005 0 -0 0</pose>
          <mass>0.7906</mass>
          <inertia>
            <ixx>0.2679</ixx>
            <ixy>0</ixy>
            <ixz>0</ixz>
            <iyy>0.2679</iyy>
            <iyz>0</iyz>
            <izz>0.0651</izz>
          </inertia>
        </inertial>
        <collision name='robot_arm_link5_collision'>
          <pose frame=''>0.005 0 -0.005 0 -0 0</pose>
          <geometry>
            <mesh>
              <scale>1 1 1</scale>
              <uri>/home/bouich/catkin_ws/src/robot_arm/meshes/Link3_section_2.stl</uri>
            </mesh>
          </geometry>
          <max_contacts>10</max_contacts>
          <surface>
            <contact>
              <ode/>
            </contact>
            <bounce/>
            <friction>
              <torsional>
                <ode/>
              </torsional>
              <ode/>
            </friction>
          </surface>
        </collision>
        <visual name='robot_arm_link5_visual'>
          <pose frame=''>0.005 0 -0.005 0 -0 0</pose>
          <geometry>
            <mesh>
              <scale>1 1 1</scale>
              <uri>/home/bouich/catkin_ws/src/robot_arm/meshes/Link3_section_2.stl</uri>
            </mesh>
          </geometry>
        </visual>
        <self_collide>0</self_collide>
        <kinematic>0</kinematic>
        <gravity>1</gravity>
      </link>
      <joint name='robot_arm_link4__robot_arm_link5' type='revolute'>
        <child>robot_arm_link5</child>
        <parent>robot_arm_link4</parent>
        <axis>
          <xyz>0 -4e-06 -1</xyz>
          <limit>
            <lower>-3.14</lower>
            <upper>3.14</upper>
            <effort>1000</effort>
            <velocity>0.5</velocity>
          </limit>
          <dynamics>
            <spring_reference>0</spring_reference>
            <spring_stiffness>0</spring_stiffness>
          </dynamics>
          <use_parent_model_frame>1</use_parent_model_frame>
        </axis>
      </joint>
      <link name='robot_arm_link6'>
        <pose frame=''>-0.007 -0.065 0.36 -0.785396 -1.57079 0.785385</pose>
        <inertial>
          <pose frame=''>0 0 0.005 0 -0 0</pose>
          <mass>0.7906</mass>
          <inertia>
            <ixx>0.2679</ixx>
            <ixy>0</ixy>
            <ixz>0</ixz>
            <iyy>0.2679</iyy>
            <iyz>0</iyz>
            <izz>0.0651</izz>
          </inertia>
        </inertial>
        <collision name='robot_arm_link6_collision'>
          <pose frame=''>0 0 0.005 0 -0 0</pose>
          <geometry>
            <mesh>
              <scale>1 1 1</scale>
              <uri>/home/bouich/catkin_ws/src/robot_arm/meshes/Link3_section_3.stl</uri>
            </mesh>
          </geometry>
          <max_contacts>10</max_contacts>
          <surface>
            <contact>
              <ode/>
            </contact>
            <bounce/>
            <friction>
              <torsional>
                <ode/>
              </torsional>
              <ode/>
            </friction>
          </surface>
        </collision>
        <visual name='robot_arm_link6_visual'>
          <pose frame=''>0 0 0.005 0 -0 0</pose>
          <geometry>
            <mesh>
              <scale>1 1 1</scale>
              <uri>/home/bouich/catkin_ws/src/robot_arm/meshes/Link3_section_3.stl</uri>
            </mesh>
          </geometry>
        </visual>
        <self_collide>0</self_collide>
        <kinematic>0</kinematic>
        <gravity>1</gravity>
      </link>
      <joint name='robot_arm_link5__robot_arm_link6' type='revolute'>
        <child>robot_arm_link6</child>
        <parent>robot_arm_link5</parent>
        <axis>
          <xyz>-1 1.1e-05 4e-06</xyz>
          <limit>
            <lower>-3.14</lower>
            <upper>3.14</upper>
            <effort>1000</effort>
            <velocity>0.5</velocity>
          </limit>
          <dynamics>
            <spring_reference>0</spring_reference>
            <spring_stiffness>0</spring_stiffness>
          </dynamics>
          <use_parent_model_frame>1</use_parent_model_frame>
        </axis>
      </joint>
      <link name='robot_arm_link7'>
        <pose frame=''>-0.019 -0.065 0.3875 1.57081 7e-06 1.57079</pose>
        <inertial>
          <pose frame=''>0 0 0 0 -0 0</pose>
          <mass>0.5906</mass>
          <inertia>
            <ixx>0.2679</ixx>
            <ixy>0</ixy>
            <ixz>0</ixz>
            <iyy>0.2679</iyy>
            <iyz>0</iyz>
            <izz>0.0651</izz>
          </inertia>
        </inertial>
        <collision name='robot_arm_link7_collision'>
          <pose frame=''>0 0 0 0 -0 0</pose>
          <geometry>
            <mesh>
              <scale>1 1 1</scale>
              <uri>/home/bouich/catkin_ws/src/robot_arm/meshes/End_Effector_Top_Jaw.stl</uri>
            </mesh>
          </geometry>
          <max_contacts>10</max_contacts>
          <surface>
            <contact>
              <ode/>
            </contact>
            <bounce/>
            <friction>
              <torsional>
                <ode/>
              </torsional>
              <ode/>
            </friction>
          </surface>
        </collision>
        <visual name='robot_arm_link7_visual'>
          <pose frame=''>0 0 0 0 -0 0</pose>
          <geometry>
            <mesh>
              <scale>1 1 1</scale>
              <uri>/home/bouich/catkin_ws/src/robot_arm/meshes/End_Effector_Top_Jaw.stl</uri>
            </mesh>
          </geometry>
        </visual>
        <self_collide>0</self_collide>
        <kinematic>0</kinematic>
        <gravity>1</gravity>
      </link>
      <joint name='robot_arm_link6__robot_arm_link7' type='revolute'>
        <child>robot_arm_link7</child>
        <parent>robot_arm_link6</parent>
        <axis>
          <xyz>1 -1.1e-05 -1.1e-05</xyz>
          <limit>
            <lower>-3.14</lower>
            <upper>3.14</upper>
            <effort>1000</effort>
            <velocity>0.5</velocity>
          </limit>
          <dynamics>
            <spring_reference>0</spring_reference>
            <spring_stiffness>0</spring_stiffness>
          </dynamics>
          <use_parent_model_frame>1</use_parent_model_frame>
        </axis>
      </joint>
      <static>0</static>
      <plugin name='gazebo_ros_control' filename='libgazebo_ros_control.so'>
        <robotNamespace>/robot_arm</robotNamespace>
        <robotParam>/robot_arm/robot_description</robotParam>
      </plugin>
      <pose frame=''>0 0 0.05 0 -0 0</pose>
    </model>
    <state world_name='default'>
      <sim_time>46 720000000</sim_time>
      <real_time>47 62631088</real_time>
      <wall_time>1616765951 479245879</wall_time>
      <iterations>46720</iterations>
      <model name='ground_plane'>
        <pose frame=''>0 0 0 0 -0 0</pose>
        <scale>1 1 1</scale>
        <link name='link'>
          <pose frame=''>0 0 0 0 -0 0</pose>
          <velocity>0 0 0 0 -0 0</velocity>
          <acceleration>0 0 0 0 -0 0</acceleration>
          <wrench>0 0 0 0 -0 0</wrench>
        </link>
      </model>
      <model name='robot_arm'>
        <pose frame=''>-1.4e-05 -2.9e-05 1e-06 -4e-06 -2.1e-05 -8.8e-05</pose>
        <scale>1 1 1</scale>
        <link name='robot_arm_base_link'>
          <pose frame=''>-1.4e-05 -2.9e-05 1e-06 -4e-06 -2.1e-05 -8.8e-05</pose>
          <velocity>1e-06 1e-06 -0.000423 0.015812 -0.009189 3.2e-05</velocity>
          <acceleration>-0.000101 -6.6e-05 -0.601735 2.49098 1.50941 -0.002456</acceleration>
          <wrench>-0.103548 -0.067879 -616.177 0 -0 0</wrench>
        </link>
        <link name='robot_arm_link2'>
          <pose frame=''>-0.005021 -0.060028 0.095001 -1.57333 1.56254 1.56814</pose>
          <velocity>-0.000869 -0.001501 -0.001418 0.00046 -0.009187 -6e-06</velocity>
          <acceleration>0.369639 -0.327261 -0.744362 1.67854 1.52045 -0.002294</acceleration>
          <wrench>2.14043 -1.89504 -4.3103 0 -0 0</wrench>
        </link>
        <link name='robot_arm_link4'>
          <pose frame=''>-0.007024 -0.061266 0.244996 3.12804 2.1e-05 3.14148</pose>
          <velocity>-0.002247 -0.00157 -0.001436 -0.003163 -0.009187 -6e-06</velocity>
          <acceleration>0.474721 -0.337244 -0.747359 0.143165 1.50988 -0.072685</acceleration>
          <wrench>0.28037 -0.199176 -0.44139 0 -0 0</wrench>
        </link>
        <link name='robot_arm_link5'>
          <pose frame=''>-0.007027 -0.067281 0.319921 3.12804 1.7e-05 3.14122</pose>
          <velocity>-0.002935 -0.001333 -0.001418 -0.003163 -0.009185 -0.000122</velocity>
          <acceleration>0.490159 -0.338807 -0.734392 0.143184 1.51055 -0.040544</acceleration>
          <wrench>0.38752 -0.267861 -0.58061 0 -0 0</wrench>
        </link>
        <link name='robot_arm_link6'>
          <pose frame=''>-0.007028 -0.067824 0.359917 1.57174 -1.55712 -1.57212</pose>
          <velocity>-0.003302 -0.001207 -0.001416 -0.003253 -0.009184 -0.000122</velocity>
          <acceleration>0.542907 -0.343821 -0.734284 -0.695565 1.50935 0.005596</acceleration>
          <wrench>0.429222 -0.271825 -0.580525 0 -0 0</wrench>
        </link>
        <link name='robot_arm_link7'>
          <pose frame=''>-0.019028 -0.068195 0.387414 1.57079 -0.014663 1.57043</pose>
          <velocity>-0.003554 -0.001116 -0.001525 -0.002574 -0.009184 -0.000122</velocity>
          <acceleration>0.584345 -0.329235 -0.723387 -0.060276 1.50899 0.005609</acceleration>
          <wrench>0.345114 -0.194446 -0.427232 0 -0 0</wrench>
        </link>
        <link name='robot_arm_turning_mount'>
          <pose frame=''>-2.2e-05 -0.070029 0.060001 -4e-06 -2.1e-05 -0.000104</pose>
          <velocity>-0.000548 -0.000948 -0.00153 0.015812 -0.009189 -6e-06</velocity>
          <acceleration>0.090305 -0.149515 -0.776123 2.49098 1.50942 -0.008745</acceleration>
          <wrench>1.42351 -2.35685 -12.2343 0 -0 0</wrench>
        </link>
      </model>
      <model name='unit_cylinder_0_0'>
        <pose frame=''>-1.4364 0.456865 0.499997 3e-06 4e-06 -0</pose>
        <scale>1 1 1</scale>
        <link name='link'>
          <pose frame=''>-0.326402 -0.103134 0.049991 3e-06 4e-06 -0</pose>
          <velocity>0 0 0 0 -0 0</velocity>
          <acceleration>0 0 0 0 -0 0</acceleration>
          <wrench>0 0 0 0 -0 0</wrench>
        </link>
      </model>
      <light name='sun'>
        <pose frame=''>0 0 10 0 -0 0</pose>
      </light>
    </state>
    <model name='unit_cylinder_0_0'>
      <link name='link'>
        <pose frame=''>1.11 -0.56 -0.45 0 -0 0</pose>
        <inertial>
          <mass>1</mass>
          <inertia>
            <ixx>0.145833</ixx>
            <ixy>0</ixy>
            <ixz>0</ixz>
            <iyy>0.145833</iyy>
            <iyz>0</iyz>
            <izz>0.125</izz>
          </inertia>
          <pose frame=''>0 0 0 0 -0 0</pose>
        </inertial>
        <self_collide>0</self_collide>
        <kinematic>0</kinematic>
        <gravity>1</gravity>
        <visual name='visual'>
          <geometry>
            <cylinder>
              <radius>0.005</radius>
              <length>0.1</length>
            </cylinder>
          </geometry>
          <material>
            <script>
              <name>Gazebo/Grey</name>
              <uri>file://media/materials/scripts/gazebo.material</uri>
            </script>
            <ambient>0.3 0.3 0.3 1</ambient>
            <diffuse>0.7 0.7 0.7 1</diffuse>
            <specular>0.01 0.01 0.01 1</specular>
            <emissive>0 0 0 1</emissive>
            <shader type='vertex'>
              <normal_map>__default__</normal_map>
            </shader>
          </material>
          <pose frame=''>0 0 0 0 -0 0</pose>
          <cast_shadows>1</cast_shadows>
          <transparency>0</transparency>
        </visual>
        <collision name='collision'>
          <laser_retro>0</laser_retro>
          <max_contacts>10</max_contacts>
          <pose frame=''>0 0 0 0 -0 0</pose>
          <geometry>
            <cylinder>
              <radius>0.005</radius>
              <length>0.1</length>
            </cylinder>
          </geometry>
          <surface>
            <friction>
              <ode>
                <mu>1</mu>
                <mu2>1</mu2>
                <fdir1>0 0 0</fdir1>
                <slip1>0</slip1>
                <slip2>0</slip2>
              </ode>
              <torsional>
                <coefficient>1</coefficient>
                <patch_radius>0</patch_radius>
                <surface_radius>0</surface_radius>
                <use_patch_radius>1</use_patch_radius>
                <ode>
                  <slip>0</slip>
                </ode>
              </torsional>
            </friction>
            <bounce>
              <restitution_coefficient>0</restitution_coefficient>
              <threshold>1e+06</threshold>
            </bounce>
            <contact>
              <collide_without_contact>0</collide_without_contact>
              <collide_without_contact_bitmask>1</collide_without_contact_bitmask>
              <collide_bitmask>1</collide_bitmask>
              <ode>
                <soft_cfm>0</soft_cfm>
                <soft_erp>0.2</soft_erp>
                <kp>1e+13</kp>
                <kd>1</kd>
                <max_vel>0.01</max_vel>
                <min_depth>0</min_depth>
              </ode>
              <bullet>
                <split_impulse>1</split_impulse>
                <split_impulse_penetration_threshold>-0.01</split_impulse_penetration_threshold>
                <soft_cfm>0</soft_cfm>
                <soft_erp>0.2</soft_erp>
                <kp>1e+13</kp>
                <kd>1</kd>
              </bullet>
            </contact>
          </surface>
        </collision>
      </link>
      <static>0</static>
      <allow_auto_disable>1</allow_auto_disable>
      <pose frame=''>-1.4364 0.456865 0.499997 3e-06 4e-06 -0</pose>
    </model>
    <gui fullscreen='0'>
      <camera name='user_camera'>
        <pose frame=''>0.350384 -0.726027 0.371023 0 0.279643 2.0442</pose>
        <view_controller>orbit</view_controller>
        <projection_type>perspective</projection_type>
      </camera>
    </gui>
  </world>
</sdf>
