<sdf version='1.6'>
  <world name='default'>
    <light name='sun' type='directional'>
      <cast_shadows>1</cast_shadows>
      <pose frame=''>0 0 10 0 -0 0</pose>
      <diffuse>0.8 0.8 0.8 1</diffuse>
      <specular>0.1 0.1 0.1 1</specular>
      <attenuation>
        <range>1000</range>
        <constant>0.9</constant>
        <linear>0.01</linear>
        <quadratic>0.001</quadratic>
      </attenuation>
      <direction>-0.5 0.5 -1</direction>
    </light>
    <model name='ground_plane'>
      <static>1</static>
      <link name='link'>
        <collision name='collision'>
          <geometry>
            <plane>
              <normal>0 0 1</normal>
              <size>100 100</size>
            </plane>
          </geometry>
          <surface>
            <friction>
              <ode>
                <mu>100</mu>
                <mu2>50</mu2>
              </ode>
              <torsional>
                <ode/>
              </torsional>
            </friction>
            <contact>
              <ode/>
            </contact>
            <bounce/>
          </surface>
          <max_contacts>10</max_contacts>
        </collision>
        <visual name='visual'>
          <cast_shadows>0</cast_shadows>
          <geometry>
            <plane>
              <normal>0 0 1</normal>
              <size>100 100</size>
            </plane>
          </geometry>
          <material>
            <script>
              <uri>file://media/materials/scripts/gazebo.material</uri>
              <name>Gazebo/Grey</name>
            </script>
          </material>
        </visual>
        <self_collide>0</self_collide>
        <kinematic>0</kinematic>
        <gravity>1</gravity>
      </link>
    </model>
    <gravity>0 0 -9.8</gravity>
    <magnetic_field>6e-06 2.3e-05 -4.2e-05</magnetic_field>
    <atmosphere type='adiabatic'/>
    <physics name='default_physics' default='0' type='ode'>
      <max_step_size>0.001</max_step_size>
      <real_time_factor>1</real_time_factor>
      <real_time_update_rate>1000</real_time_update_rate>
    </physics>
    <scene>
      <ambient>0.4 0.4 0.4 1</ambient>
      <background>0.7 0.7 0.7 1</background>
      <shadows>1</shadows>
    </scene>
    <spherical_coordinates>
      <surface_model>EARTH_WGS84</surface_model>
      <latitude_deg>0</latitude_deg>
      <longitude_deg>0</longitude_deg>
      <elevation>0</elevation>
      <heading_deg>0</heading_deg>
    </spherical_coordinates>
    <model name='robot_arm'>
      <link name='robot_arm_base_link'>
        <pose frame=''>0 0 0 0 -0 0</pose>
        <inertial>
          <pose frame=''>0 0 0 1.5708 -0 0</pose>
          <mass>1024</mass>
          <inertia>
            <ixx>170.667</ixx>
            <ixy>0</ixy>
            <ixz>0</ixz>
            <iyy>170.667</iyy>
            <iyz>0</iyz>
            <izz>170.667</izz>
          </inertia>
        </inertial>
        <collision name='robot_arm_base_link_collision'>
          <pose frame=''>0 0 0 1.5708 -0 0</pose>
          <geometry>
            <mesh>
              <scale>1 1 1</scale>
              <uri>/home/bouich/catkin_ws/src/robot_arm/meshes/Base_new.stl</uri>
            </mesh>
          </geometry>
          <max_contacts>10</max_contacts>
          <surface>
            <contact>
              <ode/>
            </contact>
            <bounce/>
            <friction>
              <torsional>
                <ode/>
              </torsional>
              <ode/>
            </friction>
          </surface>
        </collision>
        <visual name='robot_arm_base_link_visual'>
          <pose frame=''>0 0 0 1.5708 -0 0</pose>
          <geometry>
            <mesh>
              <scale>1 1 1</scale>
              <uri>/home/bouich/catkin_ws/src/robot_arm/meshes/Base_new.stl</uri>
            </mesh>
          </geometry>
        </visual>
        <self_collide>0</self_collide>
        <kinematic>0</kinematic>
        <gravity>1</gravity>
      </link>
      <link name='robot_arm_turning_mount'>
        <pose frame=''>0 -0.07 0.06 0 -0 0</pose>
        <inertial>
          <pose frame=''>0 0 0 1.5708 0 -1.5708</pose>
          <mass>15.7633</mass>
          <inertia>
            <ixx>1.3235</ixx>
            <ixy>0</ixy>
            <ixz>0</ixz>
            <iyy>1.235</iyy>
            <iyz>0</iyz>
            <izz>1.3235</izz>
          </inertia>
        </inertial>
        <collision name='robot_arm_turning_mount_collision'>
          <pose frame=''>0 0 0 1.5708 0 -1.5708</pose>
          <geometry>
            <mesh>
              <scale>1 1 1</scale>
              <uri>/home/bouich/catkin_ws/src/robot_arm/meshes/Turning_mount.stl</uri>
            </mesh>
          </geometry>
          <max_contacts>10</max_contacts>
          <surface>
            <contact>
              <ode/>
            </contact>
            <bounce/>
            <friction>
              <torsional>
                <ode/>
              </torsional>
              <ode/>
            </friction>
          </surface>
        </collision>
        <visual name='robot_arm_turning_mount_visual'>
          <pose frame=''>0 0 0 1.5708 0 -1.5708</pose>
          <geometry>
            <mesh>
              <scale>1 1 1</scale>
              <uri>/home/bouich/catkin_ws/src/robot_arm/meshes/Turning_mount.stl</uri>
            </mesh>
          </geometry>
        </visual>
        <self_collide>0</self_collide>
        <kinematic>0</kinematic>
        <gravity>1</gravity>
      </link>
      <joint name='robot_arm_base_link__robot_arm_turning_mount' type='revolute'>
        <child>robot_arm_turning_mount</child>
        <parent>robot_arm_base_link</parent>
        <axis>
          <xyz>0 0 1</xyz>
          <limit>
            <lower>-3.14</lower>
            <upper>3.14</upper>
            <effort>1000</effort>
            <velocity>0.5</velocity>
          </limit>
          <dynamics>
            <spring_reference>0</spring_reference>
            <spring_stiffness>0</spring_stiffness>
          </dynamics>
          <use_parent_model_frame>1</use_parent_model_frame>
        </axis>
      </joint>
      <link name='robot_arm_link2'>
        <pose frame=''>-0.005 -0.06 0.095 -1.57079 1.57079 1.57079</pose>
        <inertial>
          <pose frame=''>-0.15 0 0 0 -0 0</pose>
          <mass>5.7906</mass>
          <inertia>
            <ixx>1.2679</ixx>
            <ixy>0</ixy>
            <ixz>0</ixz>
            <iyy>1.2679</iyy>
            <iyz>0</iyz>
            <izz>0.0651</izz>
          </inertia>
        </inertial>
        <collision name='robot_arm_link2_collision'>
          <pose frame=''>-0.15 0 0 0 -0 0</pose>
          <geometry>
            <mesh>
              <scale>1 1 1</scale>
              <uri>/home/bouich/catkin_ws/src/robot_arm/meshes/Link1.stl</uri>
            </mesh>
          </geometry>
          <max_contacts>10</max_contacts>
          <surface>
            <contact>
              <ode/>
            </contact>
            <bounce/>
            <friction>
              <torsional>
                <ode/>
              </torsional>
              <ode/>
            </friction>
          </surface>
        </collision>
        <visual name='robot_arm_link2_visual'>
          <pose frame=''>-0.15 0 0 0 -0 0</pose>
          <geometry>
            <mesh>
              <scale>1 1 1</scale>
              <uri>/home/bouich/catkin_ws/src/robot_arm/meshes/Link1.stl</uri>
            </mesh>
          </geometry>
        </visual>
        <self_collide>0</self_collide>
        <kinematic>0</kinematic>
        <gravity>1</gravity>
      </link>
      <joint name='robot_arm_turning_mount__robot_arm_link2' type='revolute'>
        <child>robot_arm_link2</child>
        <parent>robot_arm_turning_mount</parent>
        <axis>
          <xyz>-1 7e-06 0</xyz>
          <limit>
            <lower>-2.8</lower>
            <upper>2.8</upper>
            <effort>1000</effort>
            <velocity>0.5</velocity>
          </limit>
          <dynamics>
            <spring_reference>0</spring_reference>
            <spring_stiffness>0</spring_stiffness>
          </dynamics>
          <use_parent_model_frame>1</use_parent_model_frame>
        </axis>
      </joint>
      <link name='robot_arm_link4'>
        <pose frame=''>-0.007 -0.060001 0.245 -3.14159 0 3.14158</pose>
        <inertial>
          <pose frame=''>-0.002 -0.02 -0.07 0 -0 0</pose>
          <mass>0.5906</mass>
          <inertia>
            <ixx>0.2679</ixx>
            <ixy>0</ixy>
            <ixz>0</ixz>
            <iyy>0.2679</iyy>
            <iyz>0</iyz>
            <izz>0.0651</izz>
          </inertia>
        </inertial>
        <collision name='robot_arm_link4_collision'>
          <pose frame=''>-0.002 -0.02 -0.07 0 -0 0</pose>
          <geometry>
            <mesh>
              <scale>1 1 1</scale>
              <uri>/home/bouich/catkin_ws/src/robot_arm/meshes/Link3_section_1.stl</uri>
            </mesh>
          </geometry>
          <max_contacts>10</max_contacts>
          <surface>
            <contact>
              <ode/>
            </contact>
            <bounce/>
            <friction>
              <torsional>
                <ode/>
              </torsional>
              <ode/>
            </friction>
          </surface>
        </collision>
        <visual name='robot_arm_link4_visual'>
          <pose frame=''>-0.002 -0.02 -0.07 0 -0 0</pose>
          <geometry>
            <mesh>
              <scale>1 1 1</scale>
              <uri>/home/bouich/catkin_ws/src/robot_arm/meshes/Link3_section_1.stl</uri>
            </mesh>
          </geometry>
        </visual>
        <self_collide>0</self_collide>
        <kinematic>0</kinematic>
        <gravity>1</gravity>
      </link>
      <joint name='robot_arm_link2__robot_arm_link4' type='revolute'>
        <child>robot_arm_link4</child>
        <parent>robot_arm_link2</parent>
        <axis>
          <xyz>-1 1.1e-05 0</xyz>
          <limit>
            <lower>-3.14</lower>
            <upper>3.14</upper>
            <effort>1000</effort>
            <velocity>0.5</velocity>
          </limit>
          <dynamics>
            <spring_reference>0</spring_reference>
            <spring_stiffness>0</spring_stiffness>
          </dynamics>
          <use_parent_model_frame>1</use_parent_model_frame>
        </axis>
      </joint>
      <link name='robot_arm_link5'>
        <pose frame=''>-0.007 -0.065 0.32 -3.14159 0 3.14158</pose>
        <inertial>
          <pose frame=''>0.005 0 -0.005 0 -0 0</pose>
          <mass>0.7906</mass>
          <inertia>
            <ixx>0.2679</ixx>
            <ixy>0</ixy>
            <ixz>0</ixz>
            <iyy>0.2679</iyy>
            <iyz>0</iyz>
            <izz>0.0651</izz>
          </inertia>
        </inertial>
        <collision name='robot_arm_link5_collision'>
          <pose frame=''>0.005 0 -0.005 0 -0 0</pose>
          <geometry>
            <mesh>
              <scale>1 1 1</scale>
              <uri>/home/bouich/catkin_ws/src/robot_arm/meshes/Link3_section_2.stl</uri>
            </mesh>
          </geometry>
          <max_contacts>10</max_contacts>
          <surface>
            <contact>
              <ode/>
            </contact>
            <bounce/>
            <friction>
              <torsional>
                <ode/>
              </torsional>
              <ode/>
            </friction>
          </surface>
        </collision>
        <visual name='robot_arm_link5_visual'>
          <pose frame=''>0.005 0 -0.005 0 -0 0</pose>
          <geometry>
            <mesh>
              <scale>1 1 1</scale>
              <uri>/home/bouich/catkin_ws/src/robot_arm/meshes/Link3_section_2.stl</uri>
            </mesh>
          </geometry>
        </visual>
        <self_collide>0</self_collide>
        <kinematic>0</kinematic>
        <gravity>1</gravity>
      </link>
      <joint name='robot_arm_link4__robot_arm_link5' type='revolute'>
        <child>robot_arm_link5</child>
        <parent>robot_arm_link4</parent>
        <axis>
          <xyz>0 -4e-06 -1</xyz>
          <limit>
            <lower>-3.14</lower>
            <upper>3.14</upper>
            <effort>1000</effort>
            <velocity>0.5</velocity>
          </limit>
          <dynamics>
            <spring_reference>0</spring_reference>
            <spring_stiffness>0</spring_stiffness>
          </dynamics>
          <use_parent_model_frame>1</use_parent_model_frame>
        </axis>
      </joint>
      <link name='robot_arm_link6'>
        <pose frame=''>-0.007 -0.065 0.36 -0.785396 -1.57079 0.785385</pose>
        <inertial>
          <pose frame=''>0 0 0.005 0 -0 0</pose>
          <mass>0.7906</mass>
          <inertia>
            <ixx>0.2679</ixx>
            <ixy>0</ixy>
            <ixz>0</ixz>
            <iyy>0.2679</iyy>
            <iyz>0</iyz>
            <izz>0.0651</izz>
          </inertia>
        </inertial>
        <collision name='robot_arm_link6_collision'>
          <pose frame=''>0 0 0.005 0 -0 0</pose>
          <geometry>
            <mesh>
              <scale>1 1 1</scale>
              <uri>/home/bouich/catkin_ws/src/robot_arm/meshes/Link3_section_3.stl</uri>
            </mesh>
          </geometry>
          <max_contacts>10</max_contacts>
          <surface>
            <contact>
              <ode/>
            </contact>
            <bounce/>
            <friction>
              <torsional>
                <ode/>
              </torsional>
              <ode/>
            </friction>
          </surface>
        </collision>
        <visual name='robot_arm_link6_visual'>
          <pose frame=''>0 0 0.005 0 -0 0</pose>
          <geometry>
            <mesh>
              <scale>1 1 1</scale>
              <uri>/home/bouich/catkin_ws/src/robot_arm/meshes/Link3_section_3.stl</uri>
            </mesh>
          </geometry>
        </visual>
        <self_collide>0</self_collide>
        <kinematic>0</kinematic>
        <gravity>1</gravity>
      </link>
      <joint name='robot_arm_link5__robot_arm_link6' type='revolute'>
        <child>robot_arm_link6</child>
        <parent>robot_arm_link5</parent>
        <axis>
          <xyz>-1 1.1e-05 4e-06</xyz>
          <limit>
            <lower>-3.14</lower>
            <upper>3.14</upper>
            <effort>1000</effort>
            <velocity>0.5</velocity>
          </limit>
          <dynamics>
            <spring_reference>0</spring_reference>
            <spring_stiffness>0</spring_stiffness>
          </dynamics>
          <use_parent_model_frame>1</use_parent_model_frame>
        </axis>
      </joint>
      <link name='robot_arm_link7'>
        <pose frame=''>-0.019 -0.065 0.3875 1.57081 7e-06 1.57079</pose>
        <inertial>
          <pose frame=''>0 0 0 0 -0 0</pose>
          <mass>0.5906</mass>
          <inertia>
            <ixx>0.2679</ixx>
            <ixy>0</ixy>
            <ixz>0</ixz>
            <iyy>0.2679</iyy>
            <iyz>0</iyz>
            <izz>0.0651</izz>
          </inertia>
        </inertial>
        <collision name='robot_arm_link7_collision'>
          <pose frame=''>0 0 0 0 -0 0</pose>
          <geometry>
            <mesh>
              <scale>1 1 1</scale>
              <uri>/home/bouich/catkin_ws/src/robot_arm/meshes/End_Effector_Top_Jaw.stl</uri>
            </mesh>
          </geometry>
          <max_contacts>10</max_contacts>
          <surface>
            <contact>
              <ode/>
            </contact>
            <bounce/>
            <friction>
              <torsional>
                <ode/>
              </torsional>
              <ode/>
            </friction>
          </surface>
        </collision>
        <visual name='robot_arm_link7_visual'>
          <pose frame=''>0 0 0 0 -0 0</pose>
          <geometry>
            <mesh>
              <scale>1 1 1</scale>
              <uri>/home/bouich/catkin_ws/src/robot_arm/meshes/End_Effector_Top_Jaw.stl</uri>
            </mesh>
          </geometry>
        </visual>
        <self_collide>0</self_collide>
        <kinematic>0</kinematic>
        <gravity>1</gravity>
      </link>
      <joint name='robot_arm_link6__robot_arm_link7' type='revolute'>
        <child>robot_arm_link7</child>
        <parent>robot_arm_link6</parent>
        <axis>
          <xyz>1 -1.1e-05 -1.1e-05</xyz>
          <limit>
            <lower>-3.14</lower>
            <upper>3.14</upper>
            <effort>1000</effort>
            <velocity>0.5</velocity>
          </limit>
          <dynamics>
            <spring_reference>0</spring_reference>
            <spring_stiffness>0</spring_stiffness>
          </dynamics>
          <use_parent_model_frame>1</use_parent_model_frame>
        </axis>
      </joint>
      <static>0</static>
      <plugin name='gazebo_ros_control' filename='libgazebo_ros_control.so'>
        <robotNamespace>/robot_arm</robotNamespace>
        <robotParam>/robot_arm/robot_description</robotParam>
      </plugin>
      <pose frame=''>0 0 0.05 0 -0 0</pose>
    </model>
    <state world_name='default'>
      <sim_time>738 100000000</sim_time>
      <real_time>739 529219085</real_time>
      <wall_time>1616781774 302271358</wall_time>
      <iterations>738100</iterations>
      <model name='ground_plane'>
        <pose frame=''>0 0 0 0 -0 0</pose>
        <scale>1 1 1</scale>
        <link name='link'>
          <pose frame=''>0 0 0 0 -0 0</pose>
          <velocity>0 0 0 0 -0 0</velocity>
          <acceleration>0 0 0 0 -0 0</acceleration>
          <wrench>0 0 0 0 -0 0</wrench>
        </link>
      </model>
      <model name='robot_arm'>
        <pose frame=''>-4.9e-05 0.000554 1e-06 -1e-06 1.9e-05 0.04321</pose>
        <scale>1 1 1</scale>
        <link name='robot_arm_base_link'>
          <pose frame=''>-4.9e-05 0.000554 1e-06 -1e-06 1.9e-05 0.04321</pose>
          <velocity>0 0 -0.000448 0.009965 -0.009693 2.9e-05</velocity>
          <acceleration>4.3e-05 0.000931 -9.79992 -0.001037 0.000529 2.2e-05</acceleration>
          <wrench>0.043857 0.953636 -10035.1 0 -0 0</wrench>
        </link>
        <link name='robot_arm_link2'>
          <pose frame=''>-0.00245 -0.059606 0.095001 -1.568 1.56402 1.61679</pose>
          <velocity>-0.00092 -0.000948 -0.001073 0.002764 -0.010011 -1.8e-05</velocity>
          <acceleration>-0.0002 -0.121073 -9.80447 1.01719 -1.40414 -3.141</acceleration>
          <wrench>-0.00116 -0.701087 -56.7738 0 -0 0</wrench>
        </link>
        <link name='robot_arm_link4'>
          <pose frame=''>-0.004402 -0.060707 0.244998 3.12973 -1.9e-05 -3.0984</pose>
          <velocity>-0.002423 -0.001362 -0.001098 -0.000819 -0.010169 -1.8e-05</velocity>
          <acceleration>-0.004785 -0.095757 -9.79688 -0.365472 -0.037341 -0.001957</acceleration>
          <wrench>-0.002826 -0.056554 -5.78604 0 -0 0</wrench>
        </link>
        <link name='robot_arm_link5'>
          <pose frame=''>-0.004146 -0.06659 0.319933 3.12973 -2.1e-05 -3.09859</pose>
          <velocity>-0.003188 -0.001302 -0.001087 -0.000818 -0.010175 -0.000152</velocity>
          <acceleration>-0.012849 -0.093594 -9.81159 -0.365468 -0.054545 0.007541</acceleration>
          <wrench>-0.010159 -0.073996 -7.75704 0 -0 0</wrench>
        </link>
        <link name='robot_arm_link6'>
          <pose frame=''>-0.004125 -0.067065 0.35993 1.56863 -1.55889 -1.52563</pose>
          <velocity>-0.003596 -0.001269 -0.001088 -0.000493 -0.010167 -0.000152</velocity>
          <acceleration>-0.019899 -0.081773 -9.81593 0.688649 -0.02485 0.001416</acceleration>
          <wrench>-0.015732 -0.06465 -7.76047 0 -0 0</wrench>
        </link>
        <link name='robot_arm_link7'>
          <pose frame=''>-0.016099 -0.067908 0.387429 1.57083 -0.012966 1.61381</pose>
          <velocity>-0.003877 -0.001254 -0.001211 -0.000808 -0.010185 -0.000152</velocity>
          <acceleration>-0.02418 -0.103611 -9.81965 -0.198992 -0.074043 0.001414</acceleration>
          <wrench>-0.014281 -0.061193 -5.79949 0 -0 0</wrench>
        </link>
        <link name='robot_arm_turning_mount'>
          <pose frame=''>0.002976 -0.069381 0.060001 -1e-06 1.9e-05 0.04321</pose>
          <velocity>-0.000579 -0.000598 -0.001117 0.009971 -0.009694 -1.8e-05</velocity>
          <acceleration>1.9e-05 0.000244 -9.80145 0.01233 -0.000751 -0.003139</acceleration>
          <wrench>0.000301 0.003843 -154.503 0 -0 0</wrench>
        </link>
      </model>
      <model name='unit_cylinder_0_0'>
        <pose frame=''>-1.48362 0.276549 0.500016 -7e-06 1.6e-05 -0</pose>
        <scale>1 1 1</scale>
        <link name='link'>
          <pose frame=''>-0.283631 -0.223454 0.05 -7e-06 1.6e-05 -0</pose>
          <velocity>0 0 0 0 -0 0</velocity>
          <acceleration>0 0 -9.8 0 -0 0</acceleration>
          <wrench>0 0 -0.49 0 -0 0</wrench>
        </link>
      </model>
      <light name='sun'>
        <pose frame=''>0 0 10 0 -0 0</pose>
      </light>
    </state>
    <model name='unit_cylinder_0_0'>
      <link name='link'>
        <pose frame=''>1.2 -0.5 -0.45 0 -0 0</pose>
        <inertial>
          <mass>0.05</mass>
          <inertia>
            <ixx>0.145833</ixx>
            <ixy>0</ixy>
            <ixz>0</ixz>
            <iyy>0.145833</iyy>
            <iyz>0</iyz>
            <izz>0.125</izz>
          </inertia>
          <pose frame=''>0 0 0 0 -0 0</pose>
        </inertial>
        <self_collide>0</self_collide>
        <kinematic>0</kinematic>
        <gravity>1</gravity>
        <visual name='visual'>
          <geometry>
            <cylinder>
              <radius>0.005</radius>
              <length>0.1</length>
            </cylinder>
          </geometry>
          <material>
            <script>
              <name>Gazebo/Grey</name>
              <uri>file://media/materials/scripts/gazebo.material</uri>
            </script>
            <ambient>0.3 0.3 0.3 1</ambient>
            <diffuse>0.7 0.7 0.7 1</diffuse>
            <specular>0.01 0.01 0.01 1</specular>
            <emissive>0 0 0 1</emissive>
            <shader type='vertex'>
              <normal_map>__default__</normal_map>
            </shader>
          </material>
          <pose frame=''>0 0 0 0 -0 0</pose>
          <cast_shadows>1</cast_shadows>
          <transparency>0</transparency>
        </visual>
        <collision name='collision'>
          <laser_retro>0</laser_retro>
          <max_contacts>10</max_contacts>
          <pose frame=''>0 0 0 0 -0 0</pose>
          <geometry>
            <cylinder>
              <radius>0.005</radius>
              <length>0.1</length>
            </cylinder>
          </geometry>
          <surface>
            <friction>
              <ode>
                <mu>1</mu>
                <mu2>1</mu2>
                <fdir1>0 0 0</fdir1>
                <slip1>0</slip1>
                <slip2>0</slip2>
              </ode>
              <torsional>
                <coefficient>1</coefficient>
                <patch_radius>0</patch_radius>
                <surface_radius>0</surface_radius>
                <use_patch_radius>1</use_patch_radius>
                <ode>
                  <slip>0</slip>
                </ode>
              </torsional>
            </friction>
            <bounce>
              <restitution_coefficient>0</restitution_coefficient>
              <threshold>1e+06</threshold>
            </bounce>
            <contact>
              <collide_without_contact>0</collide_without_contact>
              <collide_without_contact_bitmask>1</collide_without_contact_bitmask>
              <collide_bitmask>1</collide_bitmask>
              <ode>
                <soft_cfm>0</soft_cfm>
                <soft_erp>0.2</soft_erp>
                <kp>1e+13</kp>
                <kd>1</kd>
                <max_vel>0.01</max_vel>
                <min_depth>0</min_depth>
              </ode>
              <bullet>
                <split_impulse>1</split_impulse>
                <split_impulse_penetration_threshold>-0.01</split_impulse_penetration_threshold>
                <soft_cfm>0</soft_cfm>
                <soft_erp>0.2</soft_erp>
                <kp>1e+13</kp>
                <kd>1</kd>
              </bullet>
            </contact>
          </surface>
        </collision>
      </link>
      <static>0</static>
      <allow_auto_disable>1</allow_auto_disable>
      <pose frame=''>-1.48363 0.276544 0.499997 3e-06 4e-06 -0</pose>
    </model>
    <gui fullscreen='0'>
      <camera name='user_camera'>
        <pose frame=''>1.19927 -1.36572 0.635636 0 0.411643 2.14419</pose>
        <view_controller>orbit</view_controller>
        <projection_type>perspective</projection_type>
      </camera>
    </gui>
  </world>
</sdf>
